[27/Aug/2016 21:18:49] DEBUG [django.db.backends:89]                       (0.001) 
            SELECT name, type FROM sqlite_master
            WHERE type in ('table', 'view') AND NOT name='sqlite_sequence'
            ORDER BY name; args=None
[27/Aug/2016 21:18:49] DEBUG [django.db.backends:89]                       (0.000) SELECT "django_migrations"."app", "django_migrations"."name" FROM "django_migrations"; args=()
[27/Aug/2016 21:18:57] DEBUG [django.db.backends:89]                       (0.001) SELECT "django_session"."session_key", "django_session"."session_data", "django_session"."expire_date" FROM "django_session" WHERE ("django_session"."expire_date" > '2016-08-27 21:18:57.686293' AND "django_session"."session_key" = 't9khvll0rjth9zb77b3nsuuyeqrv2aos'); args=('2016-08-27 21:18:57.686293', 't9khvll0rjth9zb77b3nsuuyeqrv2aos')
[27/Aug/2016 21:18:58] DEBUG [django.db.backends:89]                       (0.000) SELECT "user_profile_selebuser"."id", "user_profile_selebuser"."password", "user_profile_selebuser"."last_login", "user_profile_selebuser"."is_superuser", "user_profile_selebuser"."email", "user_profile_selebuser"."first_name", "user_profile_selebuser"."last_name", "user_profile_selebuser"."is_admin", "user_profile_selebuser"."is_active", "user_profile_selebuser"."date_joined" FROM "user_profile_selebuser" WHERE "user_profile_selebuser"."id" = 2; args=(2,)
[27/Aug/2016 21:19:00] DEBUG [django.db.backends:89]                       (0.001) SELECT "django_session"."session_key", "django_session"."session_data", "django_session"."expire_date" FROM "django_session" WHERE ("django_session"."expire_date" > '2016-08-27 21:19:00.656516' AND "django_session"."session_key" = 't9khvll0rjth9zb77b3nsuuyeqrv2aos'); args=('2016-08-27 21:19:00.656516', 't9khvll0rjth9zb77b3nsuuyeqrv2aos')
[27/Aug/2016 21:19:00] DEBUG [django.db.backends:89]                       (0.000) SELECT "user_profile_selebuser"."id", "user_profile_selebuser"."password", "user_profile_selebuser"."last_login", "user_profile_selebuser"."is_superuser", "user_profile_selebuser"."email", "user_profile_selebuser"."first_name", "user_profile_selebuser"."last_name", "user_profile_selebuser"."is_admin", "user_profile_selebuser"."is_active", "user_profile_selebuser"."date_joined" FROM "user_profile_selebuser" WHERE "user_profile_selebuser"."id" = 2; args=(2,)
[27/Aug/2016 21:19:00] DEBUG [django.db.backends:89]                       (0.000) SELECT "user_packages_event"."id", "user_packages_event"."name", "user_packages_event"."slug", "user_packages_event"."date", "user_packages_event"."image" FROM "user_packages_event" INNER JOIN "user_packages_event_owners" ON ("user_packages_event"."id" = "user_packages_event_owners"."event_id") WHERE "user_packages_event_owners"."selebuser_id" = 2; args=(2,)
[27/Aug/2016 21:21:07] DEBUG [django.template:927]                       Exception while resolving variable 'is_popup' in template 'admin/login.html'.
Traceback (most recent call last):
  File "/Users/santosh/.virtualenvs/selebmvp/lib/python3.5/site-packages/django/template/base.py", line 883, in _resolve_lookup
    current = current[bit]
  File "/Users/santosh/.virtualenvs/selebmvp/lib/python3.5/site-packages/django/template/context.py", line 77, in __getitem__
    raise KeyError(key)
KeyError: 'is_popup'

During handling of the above exception, another exception occurred:

Traceback (most recent call last):
  File "/Users/santosh/.virtualenvs/selebmvp/lib/python3.5/site-packages/django/template/base.py", line 889, in _resolve_lookup
    if isinstance(current, BaseContext) and getattr(type(current), bit):
AttributeError: type object 'RequestContext' has no attribute 'is_popup'

During handling of the above exception, another exception occurred:

Traceback (most recent call last):
  File "/Users/santosh/.virtualenvs/selebmvp/lib/python3.5/site-packages/django/template/base.py", line 898, in _resolve_lookup
    current = current[int(bit)]
ValueError: invalid literal for int() with base 10: 'is_popup'

During handling of the above exception, another exception occurred:

Traceback (most recent call last):
  File "/Users/santosh/.virtualenvs/selebmvp/lib/python3.5/site-packages/django/template/base.py", line 905, in _resolve_lookup
    (bit, current))  # missing attribute
django.template.base.VariableDoesNotExist: Failed lookup for key [is_popup] in "[{'None': None, 'False': False, 'True': True}, {'user': <SimpleLazyObject: <SelebUser: santosh@eventtree.com>>, 'messages': <django.contrib.messages.storage.fallback.FallbackStorage object at 0x10903eb00>, 'csrf_token': <SimpleLazyObject: <function csrf.<locals>._get_val at 0x108f5bf28>>, 'perms': <django.contrib.auth.context_processors.PermWrapper object at 0x108fd9d68>, 'request': <WSGIRequest: GET '/adminsansan1931/login/?next=/adminsansan1931/'>, 'DEFAULT_MESSAGE_LEVELS': {'INFO': 20, 'WARNING': 30, 'SUCCESS': 25, 'DEBUG': 10, 'ERROR': 40}}, {}, {'has_permission': False, 'site': <django.contrib.sites.requests.RequestSite object at 0x108f2a630>, 'available_apps': [{'app_url': '/adminsansan1931/event_invites/', 'name': 'Event_Invites', 'models': [{'object_name': 'EventInvite', 'name': <django.utils.functional.lazy.<locals>.__proxy__ object at 0x108fdf0f0>, 'perms': {'delete': True, 'add': True, 'change': True}, 'add_url': '/adminsansan1931/event_invites/eventinvite/add/', 'admin_url': '/adminsansan1931/event_invites/eventinvite/'}, {'object_name': 'Invite', 'name': <django.utils.functional.lazy.<locals>.__proxy__ object at 0x10903e400>, 'perms': {'delete': True, 'add': True, 'change': True}, 'add_url': '/adminsansan1931/event_invites/invite/add/', 'admin_url': '/adminsansan1931/event_invites/invite/'}], 'has_module_perms': True, 'app_label': 'event_invites'}, {'app_url': '/adminsansan1931/user_packages/', 'name': 'User_Packages', 'models': [{'object_name': 'Booking', 'name': <django.utils.functional.lazy.<locals>.__proxy__ object at 0x10903e7f0>, 'perms': {'delete': True, 'add': True, 'change': True}, 'add_url': '/adminsansan1931/user_packages/booking/add/', 'admin_url': '/adminsansan1931/user_packages/booking/'}, {'object_name': 'EventPackage', 'name': <django.utils.functional.lazy.<locals>.__proxy__ object at 0x108fdf5c0>, 'perms': {'delete': True, 'add': True, 'change': True}, 'add_url': '/adminsansan1931/user_packages/eventpackage/add/', 'admin_url': '/adminsansan1931/user_packages/eventpackage/'}, {'object_name': 'Event', 'name': <django.utils.functional.lazy.<locals>.__proxy__ object at 0x108ff0d68>, 'perms': {'delete': True, 'add': True, 'change': True}, 'add_url': '/adminsansan1931/user_packages/event/add/', 'admin_url': '/adminsansan1931/user_packages/event/'}], 'has_module_perms': True, 'app_label': 'user_packages'}, {'app_url': '/adminsansan1931/user_profile/', 'name': 'User_Profile', 'models': [{'object_name': 'SelebUser', 'name': <django.utils.functional.lazy.<locals>.__proxy__ object at 0x108ff02e8>, 'perms': {'delete': True, 'add': True, 'change': True}, 'add_url': '/adminsansan1931/user_profile/selebuser/add/', 'admin_url': '/adminsansan1931/user_profile/selebuser/'}], 'has_module_perms': True, 'app_label': 'user_profile'}], 'next': '/adminsansan1931/', 'title': 'Log in', 'site_header': <django.utils.functional.lazy.<locals>.__proxy__ object at 0x108339d68>, 'site_title': <django.utils.functional.lazy.<locals>.__proxy__ object at 0x108339cc0>, 'username': 'santosh@eventtree.com', 'form': <AdminAuthenticationForm bound=False, valid=Unknown, fields=(username;password)>, 'site_name': '127.0.0.1:8000', 'LANGUAGE_BIDI': False, 'LANGUAGE_CODE': 'en-us', 'site_url': '/', 'app_path': '/adminsansan1931/login/?next=/adminsansan1931/'}]"
[27/Aug/2016 21:21:07] DEBUG [django.template:927]                       Exception while resolving variable 'is_popup' in template 'admin/login.html'.
Traceback (most recent call last):
  File "/Users/santosh/.virtualenvs/selebmvp/lib/python3.5/site-packages/django/template/base.py", line 883, in _resolve_lookup
    current = current[bit]
  File "/Users/santosh/.virtualenvs/selebmvp/lib/python3.5/site-packages/django/template/context.py", line 77, in __getitem__
    raise KeyError(key)
KeyError: 'is_popup'

During handling of the above exception, another exception occurred:

Traceback (most recent call last):
  File "/Users/santosh/.virtualenvs/selebmvp/lib/python3.5/site-packages/django/template/base.py", line 889, in _resolve_lookup
    if isinstance(current, BaseContext) and getattr(type(current), bit):
AttributeError: type object 'RequestContext' has no attribute 'is_popup'

During handling of the above exception, another exception occurred:

Traceback (most recent call last):
  File "/Users/santosh/.virtualenvs/selebmvp/lib/python3.5/site-packages/django/template/base.py", line 898, in _resolve_lookup
    current = current[int(bit)]
ValueError: invalid literal for int() with base 10: 'is_popup'

During handling of the above exception, another exception occurred:

Traceback (most recent call last):
  File "/Users/santosh/.virtualenvs/selebmvp/lib/python3.5/site-packages/django/template/base.py", line 905, in _resolve_lookup
    (bit, current))  # missing attribute
django.template.base.VariableDoesNotExist: Failed lookup for key [is_popup] in "[{'None': None, 'False': False, 'True': True}, {'user': <SimpleLazyObject: <SelebUser: santosh@eventtree.com>>, 'messages': <django.contrib.messages.storage.fallback.FallbackStorage object at 0x10903eb00>, 'csrf_token': <SimpleLazyObject: <function csrf.<locals>._get_val at 0x108f5bf28>>, 'perms': <django.contrib.auth.context_processors.PermWrapper object at 0x108fd9d68>, 'request': <WSGIRequest: GET '/adminsansan1931/login/?next=/adminsansan1931/'>, 'DEFAULT_MESSAGE_LEVELS': {'INFO': 20, 'WARNING': 30, 'SUCCESS': 25, 'DEBUG': 10, 'ERROR': 40}}, {}, {'has_permission': False, 'site': <django.contrib.sites.requests.RequestSite object at 0x108f2a630>, 'available_apps': [{'app_url': '/adminsansan1931/event_invites/', 'name': 'Event_Invites', 'models': [{'object_name': 'EventInvite', 'name': <django.utils.functional.lazy.<locals>.__proxy__ object at 0x108fdf0f0>, 'perms': {'delete': True, 'add': True, 'change': True}, 'add_url': '/adminsansan1931/event_invites/eventinvite/add/', 'admin_url': '/adminsansan1931/event_invites/eventinvite/'}, {'object_name': 'Invite', 'name': <django.utils.functional.lazy.<locals>.__proxy__ object at 0x10903e400>, 'perms': {'delete': True, 'add': True, 'change': True}, 'add_url': '/adminsansan1931/event_invites/invite/add/', 'admin_url': '/adminsansan1931/event_invites/invite/'}], 'has_module_perms': True, 'app_label': 'event_invites'}, {'app_url': '/adminsansan1931/user_packages/', 'name': 'User_Packages', 'models': [{'object_name': 'Booking', 'name': <django.utils.functional.lazy.<locals>.__proxy__ object at 0x10903e7f0>, 'perms': {'delete': True, 'add': True, 'change': True}, 'add_url': '/adminsansan1931/user_packages/booking/add/', 'admin_url': '/adminsansan1931/user_packages/booking/'}, {'object_name': 'EventPackage', 'name': <django.utils.functional.lazy.<locals>.__proxy__ object at 0x108fdf5c0>, 'perms': {'delete': True, 'add': True, 'change': True}, 'add_url': '/adminsansan1931/user_packages/eventpackage/add/', 'admin_url': '/adminsansan1931/user_packages/eventpackage/'}, {'object_name': 'Event', 'name': <django.utils.functional.lazy.<locals>.__proxy__ object at 0x108ff0d68>, 'perms': {'delete': True, 'add': True, 'change': True}, 'add_url': '/adminsansan1931/user_packages/event/add/', 'admin_url': '/adminsansan1931/user_packages/event/'}], 'has_module_perms': True, 'app_label': 'user_packages'}, {'app_url': '/adminsansan1931/user_profile/', 'name': 'User_Profile', 'models': [{'object_name': 'SelebUser', 'name': <django.utils.functional.lazy.<locals>.__proxy__ object at 0x108ff02e8>, 'perms': {'delete': True, 'add': True, 'change': True}, 'add_url': '/adminsansan1931/user_profile/selebuser/add/', 'admin_url': '/adminsansan1931/user_profile/selebuser/'}], 'has_module_perms': True, 'app_label': 'user_profile'}], 'next': '/adminsansan1931/', 'title': 'Log in', 'site_header': <django.utils.functional.lazy.<locals>.__proxy__ object at 0x108339d68>, 'site_title': <django.utils.functional.lazy.<locals>.__proxy__ object at 0x108339cc0>, 'username': 'santosh@eventtree.com', 'form': <AdminAuthenticationForm bound=False, valid=Unknown, fields=(username;password)>, 'site_name': '127.0.0.1:8000', 'LANGUAGE_BIDI': False, 'LANGUAGE_CODE': 'en-us', 'site_url': '/', 'app_path': '/adminsansan1931/login/?next=/adminsansan1931/'}]"
[27/Aug/2016 21:21:07] WARNING [django.request:182]                       Not Found: /static/admin/css/login.css
[27/Aug/2016 21:21:09] DEBUG [django.template:927]                       Exception while resolving variable 'is_popup' in template 'admin/login.html'.
Traceback (most recent call last):
  File "/Users/santosh/.virtualenvs/selebmvp/lib/python3.5/site-packages/django/template/base.py", line 883, in _resolve_lookup
    current = current[bit]
  File "/Users/santosh/.virtualenvs/selebmvp/lib/python3.5/site-packages/django/template/context.py", line 77, in __getitem__
    raise KeyError(key)
KeyError: 'is_popup'

During handling of the above exception, another exception occurred:

Traceback (most recent call last):
  File "/Users/santosh/.virtualenvs/selebmvp/lib/python3.5/site-packages/django/template/base.py", line 889, in _resolve_lookup
    if isinstance(current, BaseContext) and getattr(type(current), bit):
AttributeError: type object 'RequestContext' has no attribute 'is_popup'

During handling of the above exception, another exception occurred:

Traceback (most recent call last):
  File "/Users/santosh/.virtualenvs/selebmvp/lib/python3.5/site-packages/django/template/base.py", line 898, in _resolve_lookup
    current = current[int(bit)]
ValueError: invalid literal for int() with base 10: 'is_popup'

During handling of the above exception, another exception occurred:

Traceback (most recent call last):
  File "/Users/santosh/.virtualenvs/selebmvp/lib/python3.5/site-packages/django/template/base.py", line 905, in _resolve_lookup
    (bit, current))  # missing attribute
django.template.base.VariableDoesNotExist: Failed lookup for key [is_popup] in "[{'None': None, 'False': False, 'True': True}, {'user': <SimpleLazyObject: <SelebUser: santosh@eventtree.com>>, 'messages': <django.contrib.messages.storage.fallback.FallbackStorage object at 0x1090a09e8>, 'csrf_token': <SimpleLazyObject: <function csrf.<locals>._get_val at 0x108f800d0>>, 'perms': <django.contrib.auth.context_processors.PermWrapper object at 0x108fe7208>, 'request': <WSGIRequest: POST '/adminsansan1931/login/?next=/adminsansan1931/'>, 'DEFAULT_MESSAGE_LEVELS': {'INFO': 20, 'WARNING': 30, 'SUCCESS': 25, 'DEBUG': 10, 'ERROR': 40}}, {}, {'has_permission': False, 'site': <django.contrib.sites.requests.RequestSite object at 0x107415710>, 'available_apps': [{'app_url': '/adminsansan1931/event_invites/', 'name': 'Event_Invites', 'models': [{'object_name': 'EventInvite', 'name': <django.utils.functional.lazy.<locals>.__proxy__ object at 0x1090a0d30>, 'perms': {'delete': True, 'add': True, 'change': True}, 'add_url': '/adminsansan1931/event_invites/eventinvite/add/', 'admin_url': '/adminsansan1931/event_invites/eventinvite/'}, {'object_name': 'Invite', 'name': <django.utils.functional.lazy.<locals>.__proxy__ object at 0x1090a0be0>, 'perms': {'delete': True, 'add': True, 'change': True}, 'add_url': '/adminsansan1931/event_invites/invite/add/', 'admin_url': '/adminsansan1931/event_invites/invite/'}], 'has_module_perms': True, 'app_label': 'event_invites'}, {'app_url': '/adminsansan1931/user_packages/', 'name': 'User_Packages', 'models': [{'object_name': 'Booking', 'name': <django.utils.functional.lazy.<locals>.__proxy__ object at 0x1090a0668>, 'perms': {'delete': True, 'add': True, 'change': True}, 'add_url': '/adminsansan1931/user_packages/booking/add/', 'admin_url': '/adminsansan1931/user_packages/booking/'}, {'object_name': 'EventPackage', 'name': <django.utils.functional.lazy.<locals>.__proxy__ object at 0x1090a04e0>, 'perms': {'delete': True, 'add': True, 'change': True}, 'add_url': '/adminsansan1931/user_packages/eventpackage/add/', 'admin_url': '/adminsansan1931/user_packages/eventpackage/'}, {'object_name': 'Event', 'name': <django.utils.functional.lazy.<locals>.__proxy__ object at 0x1090a0eb8>, 'perms': {'delete': True, 'add': True, 'change': True}, 'add_url': '/adminsansan1931/user_packages/event/add/', 'admin_url': '/adminsansan1931/user_packages/event/'}], 'has_module_perms': True, 'app_label': 'user_packages'}, {'app_url': '/adminsansan1931/user_profile/', 'name': 'User_Profile', 'models': [{'object_name': 'SelebUser', 'name': <django.utils.functional.lazy.<locals>.__proxy__ object at 0x1090a0da0>, 'perms': {'delete': True, 'add': True, 'change': True}, 'add_url': '/adminsansan1931/user_profile/selebuser/add/', 'admin_url': '/adminsansan1931/user_profile/selebuser/'}], 'has_module_perms': True, 'app_label': 'user_profile'}], 'next': '/adminsansan1931/', 'title': 'Log in', 'site_header': <django.utils.functional.lazy.<locals>.__proxy__ object at 0x108339d68>, 'site_title': <django.utils.functional.lazy.<locals>.__proxy__ object at 0x108339cc0>, 'username': 'santosh@eventtree.com', 'form': <AdminAuthenticationForm bound=True, valid=False, fields=(username;password)>, 'site_name': '127.0.0.1:8000', 'LANGUAGE_BIDI': False, 'LANGUAGE_CODE': 'en-us', 'site_url': '/', 'app_path': '/adminsansan1931/login/?next=/adminsansan1931/'}]"
[27/Aug/2016 21:21:09] DEBUG [django.template:927]                       Exception while resolving variable 'is_popup' in template 'admin/login.html'.
Traceback (most recent call last):
  File "/Users/santosh/.virtualenvs/selebmvp/lib/python3.5/site-packages/django/template/base.py", line 883, in _resolve_lookup
    current = current[bit]
  File "/Users/santosh/.virtualenvs/selebmvp/lib/python3.5/site-packages/django/template/context.py", line 77, in __getitem__
    raise KeyError(key)
KeyError: 'is_popup'

During handling of the above exception, another exception occurred:

Traceback (most recent call last):
  File "/Users/santosh/.virtualenvs/selebmvp/lib/python3.5/site-packages/django/template/base.py", line 889, in _resolve_lookup
    if isinstance(current, BaseContext) and getattr(type(current), bit):
AttributeError: type object 'RequestContext' has no attribute 'is_popup'

During handling of the above exception, another exception occurred:

Traceback (most recent call last):
  File "/Users/santosh/.virtualenvs/selebmvp/lib/python3.5/site-packages/django/template/base.py", line 898, in _resolve_lookup
    current = current[int(bit)]
ValueError: invalid literal for int() with base 10: 'is_popup'

During handling of the above exception, another exception occurred:

Traceback (most recent call last):
  File "/Users/santosh/.virtualenvs/selebmvp/lib/python3.5/site-packages/django/template/base.py", line 905, in _resolve_lookup
    (bit, current))  # missing attribute
django.template.base.VariableDoesNotExist: Failed lookup for key [is_popup] in "[{'None': None, 'False': False, 'True': True}, {'user': <SimpleLazyObject: <SelebUser: santosh@eventtree.com>>, 'messages': <django.contrib.messages.storage.fallback.FallbackStorage object at 0x1090a09e8>, 'csrf_token': <SimpleLazyObject: <function csrf.<locals>._get_val at 0x108f800d0>>, 'perms': <django.contrib.auth.context_processors.PermWrapper object at 0x108fe7208>, 'request': <WSGIRequest: POST '/adminsansan1931/login/?next=/adminsansan1931/'>, 'DEFAULT_MESSAGE_LEVELS': {'INFO': 20, 'WARNING': 30, 'SUCCESS': 25, 'DEBUG': 10, 'ERROR': 40}}, {}, {'has_permission': False, 'site': <django.contrib.sites.requests.RequestSite object at 0x107415710>, 'available_apps': [{'app_url': '/adminsansan1931/event_invites/', 'name': 'Event_Invites', 'models': [{'object_name': 'EventInvite', 'name': <django.utils.functional.lazy.<locals>.__proxy__ object at 0x1090a0d30>, 'perms': {'delete': True, 'add': True, 'change': True}, 'add_url': '/adminsansan1931/event_invites/eventinvite/add/', 'admin_url': '/adminsansan1931/event_invites/eventinvite/'}, {'object_name': 'Invite', 'name': <django.utils.functional.lazy.<locals>.__proxy__ object at 0x1090a0be0>, 'perms': {'delete': True, 'add': True, 'change': True}, 'add_url': '/adminsansan1931/event_invites/invite/add/', 'admin_url': '/adminsansan1931/event_invites/invite/'}], 'has_module_perms': True, 'app_label': 'event_invites'}, {'app_url': '/adminsansan1931/user_packages/', 'name': 'User_Packages', 'models': [{'object_name': 'Booking', 'name': <django.utils.functional.lazy.<locals>.__proxy__ object at 0x1090a0668>, 'perms': {'delete': True, 'add': True, 'change': True}, 'add_url': '/adminsansan1931/user_packages/booking/add/', 'admin_url': '/adminsansan1931/user_packages/booking/'}, {'object_name': 'EventPackage', 'name': <django.utils.functional.lazy.<locals>.__proxy__ object at 0x1090a04e0>, 'perms': {'delete': True, 'add': True, 'change': True}, 'add_url': '/adminsansan1931/user_packages/eventpackage/add/', 'admin_url': '/adminsansan1931/user_packages/eventpackage/'}, {'object_name': 'Event', 'name': <django.utils.functional.lazy.<locals>.__proxy__ object at 0x1090a0eb8>, 'perms': {'delete': True, 'add': True, 'change': True}, 'add_url': '/adminsansan1931/user_packages/event/add/', 'admin_url': '/adminsansan1931/user_packages/event/'}], 'has_module_perms': True, 'app_label': 'user_packages'}, {'app_url': '/adminsansan1931/user_profile/', 'name': 'User_Profile', 'models': [{'object_name': 'SelebUser', 'name': <django.utils.functional.lazy.<locals>.__proxy__ object at 0x1090a0da0>, 'perms': {'delete': True, 'add': True, 'change': True}, 'add_url': '/adminsansan1931/user_profile/selebuser/add/', 'admin_url': '/adminsansan1931/user_profile/selebuser/'}], 'has_module_perms': True, 'app_label': 'user_profile'}], 'next': '/adminsansan1931/', 'title': 'Log in', 'site_header': <django.utils.functional.lazy.<locals>.__proxy__ object at 0x108339d68>, 'site_title': <django.utils.functional.lazy.<locals>.__proxy__ object at 0x108339cc0>, 'username': 'santosh@eventtree.com', 'form': <AdminAuthenticationForm bound=True, valid=False, fields=(username;password)>, 'site_name': '127.0.0.1:8000', 'LANGUAGE_BIDI': False, 'LANGUAGE_CODE': 'en-us', 'site_url': '/', 'app_path': '/adminsansan1931/login/?next=/adminsansan1931/'}]"
[27/Aug/2016 21:21:09] WARNING [django.request:182]                       Not Found: /static/admin/css/login.css
[27/Aug/2016 21:21:21] DEBUG [django.template:927]                       Exception while resolving variable 'is_popup' in template 'admin/index.html'.
Traceback (most recent call last):
  File "/Users/santosh/.virtualenvs/selebmvp/lib/python3.5/site-packages/django/template/base.py", line 883, in _resolve_lookup
    current = current[bit]
  File "/Users/santosh/.virtualenvs/selebmvp/lib/python3.5/site-packages/django/template/context.py", line 77, in __getitem__
    raise KeyError(key)
KeyError: 'is_popup'

During handling of the above exception, another exception occurred:

Traceback (most recent call last):
  File "/Users/santosh/.virtualenvs/selebmvp/lib/python3.5/site-packages/django/template/base.py", line 889, in _resolve_lookup
    if isinstance(current, BaseContext) and getattr(type(current), bit):
AttributeError: type object 'RequestContext' has no attribute 'is_popup'

During handling of the above exception, another exception occurred:

Traceback (most recent call last):
  File "/Users/santosh/.virtualenvs/selebmvp/lib/python3.5/site-packages/django/template/base.py", line 898, in _resolve_lookup
    current = current[int(bit)]
ValueError: invalid literal for int() with base 10: 'is_popup'

During handling of the above exception, another exception occurred:

Traceback (most recent call last):
  File "/Users/santosh/.virtualenvs/selebmvp/lib/python3.5/site-packages/django/template/base.py", line 905, in _resolve_lookup
    (bit, current))  # missing attribute
django.template.base.VariableDoesNotExist: Failed lookup for key [is_popup] in "[{'None': None, 'False': False, 'True': True}, {'user': <SimpleLazyObject: <SelebUser: support@eventtree.com>>, 'messages': <django.contrib.messages.storage.fallback.FallbackStorage object at 0x108fd9ef0>, 'csrf_token': <SimpleLazyObject: <function csrf.<locals>._get_val at 0x109043158>>, 'perms': <django.contrib.auth.context_processors.PermWrapper object at 0x10904eb00>, 'request': <WSGIRequest: GET '/adminsansan1931/'>, 'DEFAULT_MESSAGE_LEVELS': {'INFO': 20, 'WARNING': 30, 'SUCCESS': 25, 'DEBUG': 10, 'ERROR': 40}}, {}, {'has_permission': True, 'site_title': <django.utils.functional.lazy.<locals>.__proxy__ object at 0x108339cc0>, 'title': <django.utils.functional.lazy.<locals>.__proxy__ object at 0x108341208>, 'LANGUAGE_BIDI': False, 'LANGUAGE_CODE': 'en-us', 'site_url': '/', 'site_header': <django.utils.functional.lazy.<locals>.__proxy__ object at 0x108339d68>, 'available_apps': [{'app_url': '/adminsansan1931/event_invites/', 'name': 'Event_Invites', 'models': [{'object_name': 'EventInvite', 'name': <django.utils.functional.lazy.<locals>.__proxy__ object at 0x108fd9b70>, 'perms': {'delete': True, 'add': True, 'change': True}, 'add_url': '/adminsansan1931/event_invites/eventinvite/add/', 'admin_url': '/adminsansan1931/event_invites/eventinvite/'}, {'object_name': 'Invite', 'name': <django.utils.functional.lazy.<locals>.__proxy__ object at 0x108fd9240>, 'perms': {'delete': True, 'add': True, 'change': True}, 'add_url': '/adminsansan1931/event_invites/invite/add/', 'admin_url': '/adminsansan1931/event_invites/invite/'}], 'has_module_perms': True, 'app_label': 'event_invites'}, {'app_url': '/adminsansan1931/user_packages/', 'name': 'User_Packages', 'models': [{'object_name': 'Booking', 'name': <django.utils.functional.lazy.<locals>.__proxy__ object at 0x108fd9470>, 'perms': {'delete': True, 'add': True, 'change': True}, 'add_url': '/adminsansan1931/user_packages/booking/add/', 'admin_url': '/adminsansan1931/user_packages/booking/'}, {'object_name': 'EventPackage', 'name': <django.utils.functional.lazy.<locals>.__proxy__ object at 0x108fd97b8>, 'perms': {'delete': True, 'add': True, 'change': True}, 'add_url': '/adminsansan1931/user_packages/eventpackage/add/', 'admin_url': '/adminsansan1931/user_packages/eventpackage/'}, {'object_name': 'Event', 'name': <django.utils.functional.lazy.<locals>.__proxy__ object at 0x108fd9198>, 'perms': {'delete': True, 'add': True, 'change': True}, 'add_url': '/adminsansan1931/user_packages/event/add/', 'admin_url': '/adminsansan1931/user_packages/event/'}], 'has_module_perms': True, 'app_label': 'user_packages'}, {'app_url': '/adminsansan1931/user_profile/', 'name': 'User_Profile', 'models': [{'object_name': 'SelebUser', 'name': <django.utils.functional.lazy.<locals>.__proxy__ object at 0x108fd9320>, 'perms': {'delete': True, 'add': True, 'change': True}, 'add_url': '/adminsansan1931/user_profile/selebuser/add/', 'admin_url': '/adminsansan1931/user_profile/selebuser/'}], 'has_module_perms': True, 'app_label': 'user_profile'}], 'app_list': [{'app_url': '/adminsansan1931/event_invites/', 'name': 'Event_Invites', 'models': [{'object_name': 'EventInvite', 'name': <django.utils.functional.lazy.<locals>.__proxy__ object at 0x108fd9128>, 'perms': {'delete': True, 'add': True, 'change': True}, 'add_url': '/adminsansan1931/event_invites/eventinvite/add/', 'admin_url': '/adminsansan1931/event_invites/eventinvite/'}, {'object_name': 'Invite', 'name': <django.utils.functional.lazy.<locals>.__proxy__ object at 0x108fd9518>, 'perms': {'delete': True, 'add': True, 'change': True}, 'add_url': '/adminsansan1931/event_invites/invite/add/', 'admin_url': '/adminsansan1931/event_invites/invite/'}], 'has_module_perms': True, 'app_label': 'event_invites'}, {'app_url': '/adminsansan1931/user_packages/', 'name': 'User_Packages', 'models': [{'object_name': 'Booking', 'name': <django.utils.functional.lazy.<locals>.__proxy__ object at 0x108fd9fd0>, 'perms': {'delete': True, 'add': True, 'change': True}, 'add_url': '/adminsansan1931/user_packages/booking/add/', 'admin_url': '/adminsansan1931/user_packages/booking/'}, {'object_name': 'EventPackage', 'name': <django.utils.functional.lazy.<locals>.__proxy__ object at 0x108fd94e0>, 'perms': {'delete': True, 'add': True, 'change': True}, 'add_url': '/adminsansan1931/user_packages/eventpackage/add/', 'admin_url': '/adminsansan1931/user_packages/eventpackage/'}, {'object_name': 'Event', 'name': <django.utils.functional.lazy.<locals>.__proxy__ object at 0x108fd9f98>, 'perms': {'delete': True, 'add': True, 'change': True}, 'add_url': '/adminsansan1931/user_packages/event/add/', 'admin_url': '/adminsansan1931/user_packages/event/'}], 'has_module_perms': True, 'app_label': 'user_packages'}, {'app_url': '/adminsansan1931/user_profile/', 'name': 'User_Profile', 'models': [{'object_name': 'SelebUser', 'name': <django.utils.functional.lazy.<locals>.__proxy__ object at 0x108fd9dd8>, 'perms': {'delete': True, 'add': True, 'change': True}, 'add_url': '/adminsansan1931/user_profile/selebuser/add/', 'admin_url': '/adminsansan1931/user_profile/selebuser/'}], 'has_module_perms': True, 'app_label': 'user_profile'}]}]"
[27/Aug/2016 21:21:21] DEBUG [django.template:927]                       Exception while resolving variable 'is_popup' in template 'admin/index.html'.
Traceback (most recent call last):
  File "/Users/santosh/.virtualenvs/selebmvp/lib/python3.5/site-packages/django/template/base.py", line 883, in _resolve_lookup
    current = current[bit]
  File "/Users/santosh/.virtualenvs/selebmvp/lib/python3.5/site-packages/django/template/context.py", line 77, in __getitem__
    raise KeyError(key)
KeyError: 'is_popup'

During handling of the above exception, another exception occurred:

Traceback (most recent call last):
  File "/Users/santosh/.virtualenvs/selebmvp/lib/python3.5/site-packages/django/template/base.py", line 889, in _resolve_lookup
    if isinstance(current, BaseContext) and getattr(type(current), bit):
AttributeError: type object 'RequestContext' has no attribute 'is_popup'

During handling of the above exception, another exception occurred:

Traceback (most recent call last):
  File "/Users/santosh/.virtualenvs/selebmvp/lib/python3.5/site-packages/django/template/base.py", line 898, in _resolve_lookup
    current = current[int(bit)]
ValueError: invalid literal for int() with base 10: 'is_popup'

During handling of the above exception, another exception occurred:

Traceback (most recent call last):
  File "/Users/santosh/.virtualenvs/selebmvp/lib/python3.5/site-packages/django/template/base.py", line 905, in _resolve_lookup
    (bit, current))  # missing attribute
django.template.base.VariableDoesNotExist: Failed lookup for key [is_popup] in "[{'None': None, 'False': False, 'True': True}, {'user': <SimpleLazyObject: <SelebUser: support@eventtree.com>>, 'messages': <django.contrib.messages.storage.fallback.FallbackStorage object at 0x108fd9ef0>, 'csrf_token': <SimpleLazyObject: <function csrf.<locals>._get_val at 0x109043158>>, 'perms': <django.contrib.auth.context_processors.PermWrapper object at 0x10904eb00>, 'request': <WSGIRequest: GET '/adminsansan1931/'>, 'DEFAULT_MESSAGE_LEVELS': {'INFO': 20, 'WARNING': 30, 'SUCCESS': 25, 'DEBUG': 10, 'ERROR': 40}}, {}, {'has_permission': True, 'site_title': <django.utils.functional.lazy.<locals>.__proxy__ object at 0x108339cc0>, 'title': <django.utils.functional.lazy.<locals>.__proxy__ object at 0x108341208>, 'LANGUAGE_BIDI': False, 'LANGUAGE_CODE': 'en-us', 'site_url': '/', 'site_header': <django.utils.functional.lazy.<locals>.__proxy__ object at 0x108339d68>, 'available_apps': [{'app_url': '/adminsansan1931/event_invites/', 'name': 'Event_Invites', 'models': [{'object_name': 'EventInvite', 'name': <django.utils.functional.lazy.<locals>.__proxy__ object at 0x108fd9b70>, 'perms': {'delete': True, 'add': True, 'change': True}, 'add_url': '/adminsansan1931/event_invites/eventinvite/add/', 'admin_url': '/adminsansan1931/event_invites/eventinvite/'}, {'object_name': 'Invite', 'name': <django.utils.functional.lazy.<locals>.__proxy__ object at 0x108fd9240>, 'perms': {'delete': True, 'add': True, 'change': True}, 'add_url': '/adminsansan1931/event_invites/invite/add/', 'admin_url': '/adminsansan1931/event_invites/invite/'}], 'has_module_perms': True, 'app_label': 'event_invites'}, {'app_url': '/adminsansan1931/user_packages/', 'name': 'User_Packages', 'models': [{'object_name': 'Booking', 'name': <django.utils.functional.lazy.<locals>.__proxy__ object at 0x108fd9470>, 'perms': {'delete': True, 'add': True, 'change': True}, 'add_url': '/adminsansan1931/user_packages/booking/add/', 'admin_url': '/adminsansan1931/user_packages/booking/'}, {'object_name': 'EventPackage', 'name': <django.utils.functional.lazy.<locals>.__proxy__ object at 0x108fd97b8>, 'perms': {'delete': True, 'add': True, 'change': True}, 'add_url': '/adminsansan1931/user_packages/eventpackage/add/', 'admin_url': '/adminsansan1931/user_packages/eventpackage/'}, {'object_name': 'Event', 'name': <django.utils.functional.lazy.<locals>.__proxy__ object at 0x108fd9198>, 'perms': {'delete': True, 'add': True, 'change': True}, 'add_url': '/adminsansan1931/user_packages/event/add/', 'admin_url': '/adminsansan1931/user_packages/event/'}], 'has_module_perms': True, 'app_label': 'user_packages'}, {'app_url': '/adminsansan1931/user_profile/', 'name': 'User_Profile', 'models': [{'object_name': 'SelebUser', 'name': <django.utils.functional.lazy.<locals>.__proxy__ object at 0x108fd9320>, 'perms': {'delete': True, 'add': True, 'change': True}, 'add_url': '/adminsansan1931/user_profile/selebuser/add/', 'admin_url': '/adminsansan1931/user_profile/selebuser/'}], 'has_module_perms': True, 'app_label': 'user_profile'}], 'app_list': [{'app_url': '/adminsansan1931/event_invites/', 'name': 'Event_Invites', 'models': [{'object_name': 'EventInvite', 'name': <django.utils.functional.lazy.<locals>.__proxy__ object at 0x108fd9128>, 'perms': {'delete': True, 'add': True, 'change': True}, 'add_url': '/adminsansan1931/event_invites/eventinvite/add/', 'admin_url': '/adminsansan1931/event_invites/eventinvite/'}, {'object_name': 'Invite', 'name': <django.utils.functional.lazy.<locals>.__proxy__ object at 0x108fd9518>, 'perms': {'delete': True, 'add': True, 'change': True}, 'add_url': '/adminsansan1931/event_invites/invite/add/', 'admin_url': '/adminsansan1931/event_invites/invite/'}], 'has_module_perms': True, 'app_label': 'event_invites'}, {'app_url': '/adminsansan1931/user_packages/', 'name': 'User_Packages', 'models': [{'object_name': 'Booking', 'name': <django.utils.functional.lazy.<locals>.__proxy__ object at 0x108fd9fd0>, 'perms': {'delete': True, 'add': True, 'change': True}, 'add_url': '/adminsansan1931/user_packages/booking/add/', 'admin_url': '/adminsansan1931/user_packages/booking/'}, {'object_name': 'EventPackage', 'name': <django.utils.functional.lazy.<locals>.__proxy__ object at 0x108fd94e0>, 'perms': {'delete': True, 'add': True, 'change': True}, 'add_url': '/adminsansan1931/user_packages/eventpackage/add/', 'admin_url': '/adminsansan1931/user_packages/eventpackage/'}, {'object_name': 'Event', 'name': <django.utils.functional.lazy.<locals>.__proxy__ object at 0x108fd9f98>, 'perms': {'delete': True, 'add': True, 'change': True}, 'add_url': '/adminsansan1931/user_packages/event/add/', 'admin_url': '/adminsansan1931/user_packages/event/'}], 'has_module_perms': True, 'app_label': 'user_packages'}, {'app_url': '/adminsansan1931/user_profile/', 'name': 'User_Profile', 'models': [{'object_name': 'SelebUser', 'name': <django.utils.functional.lazy.<locals>.__proxy__ object at 0x108fd9dd8>, 'perms': {'delete': True, 'add': True, 'change': True}, 'add_url': '/adminsansan1931/user_profile/selebuser/add/', 'admin_url': '/adminsansan1931/user_profile/selebuser/'}], 'has_module_perms': True, 'app_label': 'user_profile'}]}]"
[27/Aug/2016 21:21:27] DEBUG [django.template:927]                       Exception while resolving variable 'invite' in template 'event_packages.html'.
Traceback (most recent call last):
  File "/Users/santosh/.virtualenvs/selebmvp/lib/python3.5/site-packages/django/template/base.py", line 883, in _resolve_lookup
    current = current[bit]
TypeError: 'Event' object is not subscriptable

During handling of the above exception, another exception occurred:

Traceback (most recent call last):
  File "/Users/santosh/.virtualenvs/selebmvp/lib/python3.5/site-packages/django/template/base.py", line 891, in _resolve_lookup
    current = getattr(current, bit)
  File "/Users/santosh/.virtualenvs/selebmvp/lib/python3.5/site-packages/django/db/models/fields/related_descriptors.py", line 355, in __get__
    self.related.get_accessor_name()
django.db.models.fields.related_descriptors.RelatedObjectDoesNotExist: Event has no invite.
[27/Aug/2016 21:21:28] DEBUG [django.template:927]                       Exception while resolving variable 'invite' in template 'event_packages.html'.
Traceback (most recent call last):
  File "/Users/santosh/.virtualenvs/selebmvp/lib/python3.5/site-packages/django/template/base.py", line 883, in _resolve_lookup
    current = current[bit]
TypeError: 'Event' object is not subscriptable

During handling of the above exception, another exception occurred:

Traceback (most recent call last):
  File "/Users/santosh/.virtualenvs/selebmvp/lib/python3.5/site-packages/django/template/base.py", line 891, in _resolve_lookup
    current = getattr(current, bit)
  File "/Users/santosh/.virtualenvs/selebmvp/lib/python3.5/site-packages/django/db/models/fields/related_descriptors.py", line 355, in __get__
    self.related.get_accessor_name()
django.db.models.fields.related_descriptors.RelatedObjectDoesNotExist: Event has no invite.
[27/Aug/2016 21:21:28] DEBUG [django.template:927]                       Exception while resolving variable 'status' in template 'event_packages.html'.
Traceback (most recent call last):
  File "/Users/santosh/.virtualenvs/selebmvp/lib/python3.5/site-packages/django/template/base.py", line 883, in _resolve_lookup
    current = current[bit]
TypeError: 'RelatedManager' object is not subscriptable

During handling of the above exception, another exception occurred:

Traceback (most recent call last):
  File "/Users/santosh/.virtualenvs/selebmvp/lib/python3.5/site-packages/django/template/base.py", line 891, in _resolve_lookup
    current = getattr(current, bit)
AttributeError: 'RelatedManager' object has no attribute 'status'

During handling of the above exception, another exception occurred:

Traceback (most recent call last):
  File "/Users/santosh/.virtualenvs/selebmvp/lib/python3.5/site-packages/django/template/base.py", line 898, in _resolve_lookup
    current = current[int(bit)]
ValueError: invalid literal for int() with base 10: 'status'

During handling of the above exception, another exception occurred:

Traceback (most recent call last):
  File "/Users/santosh/.virtualenvs/selebmvp/lib/python3.5/site-packages/django/template/base.py", line 905, in _resolve_lookup
    (bit, current))  # missing attribute
django.template.base.VariableDoesNotExist: Failed lookup for key [status] in 'user_packages.Booking.None'
[27/Aug/2016 21:21:42] DEBUG [django.template:927]                       Exception while resolving variable 'errors' in template 'admin/change_list.html'.
Traceback (most recent call last):
  File "/Users/santosh/.virtualenvs/selebmvp/lib/python3.5/site-packages/django/template/base.py", line 883, in _resolve_lookup
    current = current[bit]
TypeError: 'NoneType' object is not subscriptable

During handling of the above exception, another exception occurred:

Traceback (most recent call last):
  File "/Users/santosh/.virtualenvs/selebmvp/lib/python3.5/site-packages/django/template/base.py", line 891, in _resolve_lookup
    current = getattr(current, bit)
AttributeError: 'NoneType' object has no attribute 'errors'

During handling of the above exception, another exception occurred:

Traceback (most recent call last):
  File "/Users/santosh/.virtualenvs/selebmvp/lib/python3.5/site-packages/django/template/base.py", line 898, in _resolve_lookup
    current = current[int(bit)]
ValueError: invalid literal for int() with base 10: 'errors'

During handling of the above exception, another exception occurred:

Traceback (most recent call last):
  File "/Users/santosh/.virtualenvs/selebmvp/lib/python3.5/site-packages/django/template/base.py", line 905, in _resolve_lookup
    (bit, current))  # missing attribute
django.template.base.VariableDoesNotExist: Failed lookup for key [errors] in 'None'
[27/Aug/2016 21:21:42] DEBUG [django.template:927]                       Exception while resolving variable 'show' in template 'admin/change_list.html'.
Traceback (most recent call last):
  File "/Users/santosh/.virtualenvs/selebmvp/lib/python3.5/site-packages/django/template/base.py", line 883, in _resolve_lookup
    current = current[bit]
  File "/Users/santosh/.virtualenvs/selebmvp/lib/python3.5/site-packages/django/template/context.py", line 77, in __getitem__
    raise KeyError(key)
KeyError: 'show'

During handling of the above exception, another exception occurred:

Traceback (most recent call last):
  File "/Users/santosh/.virtualenvs/selebmvp/lib/python3.5/site-packages/django/template/base.py", line 889, in _resolve_lookup
    if isinstance(current, BaseContext) and getattr(type(current), bit):
AttributeError: type object 'RequestContext' has no attribute 'show'

During handling of the above exception, another exception occurred:

Traceback (most recent call last):
  File "/Users/santosh/.virtualenvs/selebmvp/lib/python3.5/site-packages/django/template/base.py", line 898, in _resolve_lookup
    current = current[int(bit)]
ValueError: invalid literal for int() with base 10: 'show'

During handling of the above exception, another exception occurred:

Traceback (most recent call last):
  File "/Users/santosh/.virtualenvs/selebmvp/lib/python3.5/site-packages/django/template/base.py", line 905, in _resolve_lookup
    (bit, current))  # missing attribute
django.template.base.VariableDoesNotExist: Failed lookup for key [show] in "[{'None': None, 'csrf_token': <SimpleLazyObject: <function csrf.<locals>._get_val at 0x1090b2400>>, 'False': False, 'True': True}]"
[27/Aug/2016 21:21:42] DEBUG [django.template:927]                       Exception while resolving variable 'is_multipart' in template 'admin/change_list.html'.
Traceback (most recent call last):
  File "/Users/santosh/.virtualenvs/selebmvp/lib/python3.5/site-packages/django/template/base.py", line 883, in _resolve_lookup
    current = current[bit]
TypeError: 'NoneType' object is not subscriptable

During handling of the above exception, another exception occurred:

Traceback (most recent call last):
  File "/Users/santosh/.virtualenvs/selebmvp/lib/python3.5/site-packages/django/template/base.py", line 891, in _resolve_lookup
    current = getattr(current, bit)
AttributeError: 'NoneType' object has no attribute 'is_multipart'

During handling of the above exception, another exception occurred:

Traceback (most recent call last):
  File "/Users/santosh/.virtualenvs/selebmvp/lib/python3.5/site-packages/django/template/base.py", line 898, in _resolve_lookup
    current = current[int(bit)]
ValueError: invalid literal for int() with base 10: 'is_multipart'

During handling of the above exception, another exception occurred:

Traceback (most recent call last):
  File "/Users/santosh/.virtualenvs/selebmvp/lib/python3.5/site-packages/django/template/base.py", line 905, in _resolve_lookup
    (bit, current))  # missing attribute
django.template.base.VariableDoesNotExist: Failed lookup for key [is_multipart] in 'None'
[27/Aug/2016 21:21:42] DEBUG [django.template:927]                       Exception while resolving variable 'non_field_errors' in template 'admin/change_list.html'.
Traceback (most recent call last):
  File "/Users/santosh/.virtualenvs/selebmvp/lib/python3.5/site-packages/django/template/base.py", line 883, in _resolve_lookup
    current = current[bit]
TypeError: 'NoneType' object is not subscriptable

During handling of the above exception, another exception occurred:

Traceback (most recent call last):
  File "/Users/santosh/.virtualenvs/selebmvp/lib/python3.5/site-packages/django/template/base.py", line 891, in _resolve_lookup
    current = getattr(current, bit)
AttributeError: 'NoneType' object has no attribute 'non_field_errors'

During handling of the above exception, another exception occurred:

Traceback (most recent call last):
  File "/Users/santosh/.virtualenvs/selebmvp/lib/python3.5/site-packages/django/template/base.py", line 898, in _resolve_lookup
    current = current[int(bit)]
ValueError: invalid literal for int() with base 10: 'non_field_errors'

During handling of the above exception, another exception occurred:

Traceback (most recent call last):
  File "/Users/santosh/.virtualenvs/selebmvp/lib/python3.5/site-packages/django/template/base.py", line 905, in _resolve_lookup
    (bit, current))  # missing attribute
django.template.base.VariableDoesNotExist: Failed lookup for key [non_field_errors] in 'None'
[27/Aug/2016 21:21:42] DEBUG [django.template:927]                       Exception while resolving variable 'non_field_errors' in template 'admin/change_list.html'.
Traceback (most recent call last):
  File "/Users/santosh/.virtualenvs/selebmvp/lib/python3.5/site-packages/django/template/base.py", line 883, in _resolve_lookup
    current = current[bit]
TypeError: 'NoneType' object is not subscriptable

During handling of the above exception, another exception occurred:

Traceback (most recent call last):
  File "/Users/santosh/.virtualenvs/selebmvp/lib/python3.5/site-packages/django/template/base.py", line 891, in _resolve_lookup
    current = getattr(current, bit)
AttributeError: 'NoneType' object has no attribute 'non_field_errors'

During handling of the above exception, another exception occurred:

Traceback (most recent call last):
  File "/Users/santosh/.virtualenvs/selebmvp/lib/python3.5/site-packages/django/template/base.py", line 898, in _resolve_lookup
    current = current[int(bit)]
ValueError: invalid literal for int() with base 10: 'non_field_errors'

During handling of the above exception, another exception occurred:

Traceback (most recent call last):
  File "/Users/santosh/.virtualenvs/selebmvp/lib/python3.5/site-packages/django/template/base.py", line 905, in _resolve_lookup
    (bit, current))  # missing attribute
django.template.base.VariableDoesNotExist: Failed lookup for key [non_field_errors] in 'None'
[27/Aug/2016 21:21:42] DEBUG [django.template:927]                       Exception while resolving variable 'non_field_errors' in template 'admin/change_list.html'.
Traceback (most recent call last):
  File "/Users/santosh/.virtualenvs/selebmvp/lib/python3.5/site-packages/django/template/base.py", line 883, in _resolve_lookup
    current = current[bit]
TypeError: 'NoneType' object is not subscriptable

During handling of the above exception, another exception occurred:

Traceback (most recent call last):
  File "/Users/santosh/.virtualenvs/selebmvp/lib/python3.5/site-packages/django/template/base.py", line 891, in _resolve_lookup
    current = getattr(current, bit)
AttributeError: 'NoneType' object has no attribute 'non_field_errors'

During handling of the above exception, another exception occurred:

Traceback (most recent call last):
  File "/Users/santosh/.virtualenvs/selebmvp/lib/python3.5/site-packages/django/template/base.py", line 898, in _resolve_lookup
    current = current[int(bit)]
ValueError: invalid literal for int() with base 10: 'non_field_errors'

During handling of the above exception, another exception occurred:

Traceback (most recent call last):
  File "/Users/santosh/.virtualenvs/selebmvp/lib/python3.5/site-packages/django/template/base.py", line 905, in _resolve_lookup
    (bit, current))  # missing attribute
django.template.base.VariableDoesNotExist: Failed lookup for key [non_field_errors] in 'None'
[27/Aug/2016 21:21:42] WARNING [django.request:182]                       Not Found: /static/admin/js/vendor/jquery/jquery.min.js
[27/Aug/2016 21:21:42] WARNING [django.request:182]                       Not Found: /static/admin/js/actions.min.js
[27/Aug/2016 21:21:42] WARNING [django.request:182]                       Not Found: /static/admin/js/prepopulate.min.js
[27/Aug/2016 21:21:42] WARNING [django.request:182]                       Not Found: /static/admin/js/vendor/jquery/jquery.min.js
[27/Aug/2016 21:21:42] WARNING [django.request:182]                       Not Found: /static/admin/js/actions.min.js
[27/Aug/2016 21:21:42] WARNING [django.request:182]                       Not Found: /static/admin/js/prepopulate.min.js
[27/Aug/2016 21:21:47] DEBUG [django.template:927]                       Exception while resolving variable 'can_delete_related' in template 'admin/related_widget_wrapper.html'.
Traceback (most recent call last):
  File "/Users/santosh/.virtualenvs/selebmvp/lib/python3.5/site-packages/django/template/base.py", line 883, in _resolve_lookup
    current = current[bit]
  File "/Users/santosh/.virtualenvs/selebmvp/lib/python3.5/site-packages/django/template/context.py", line 77, in __getitem__
    raise KeyError(key)
KeyError: 'can_delete_related'

During handling of the above exception, another exception occurred:

Traceback (most recent call last):
  File "/Users/santosh/.virtualenvs/selebmvp/lib/python3.5/site-packages/django/template/base.py", line 889, in _resolve_lookup
    if isinstance(current, BaseContext) and getattr(type(current), bit):
AttributeError: type object 'Context' has no attribute 'can_delete_related'

During handling of the above exception, another exception occurred:

Traceback (most recent call last):
  File "/Users/santosh/.virtualenvs/selebmvp/lib/python3.5/site-packages/django/template/base.py", line 898, in _resolve_lookup
    current = current[int(bit)]
ValueError: invalid literal for int() with base 10: 'can_delete_related'

During handling of the above exception, another exception occurred:

Traceback (most recent call last):
  File "/Users/santosh/.virtualenvs/selebmvp/lib/python3.5/site-packages/django/template/base.py", line 905, in _resolve_lookup
    (bit, current))  # missing attribute
django.template.base.VariableDoesNotExist: Failed lookup for key [can_delete_related] in '[{\'None\': None, \'False\': False, \'True\': True}, {\'add_related_url\': \'/adminsansan1931/user_packages/event/add/\', \'widget\': \'<select id="id_event" name="event">\\n<option value="" selected="selected">---------</option>\\n<option value="1">anjali-bday</option>\\n<option value="2">eshaans_birthday_party_01</option>\\n</select>\', \'url_params\': \'_to_field=id&_popup=1\', \'model\': \'event\', \'change_related_template_url\': \'/adminsansan1931/user_packages/event/__fk__/change/\', \'name\': \'event\', \'can_add_related\': True, \'can_change_related\': True}, {\'block\': <Block Node: links. Contents: [<TextNode: \'\\n        \'>, <IfNode>, <TextNode: \'\\n        \'>, <IfNode>, <TextNode: \'\\n        \'>, <IfNode>, <TextNode: \'\\n    \'>]>}]'
[27/Aug/2016 21:21:47] WARNING [django.request:182]                       Not Found: /static/admin/js/vendor/jquery/jquery.min.js
[27/Aug/2016 21:21:47] WARNING [django.request:182]                       Not Found: /static/admin/js/actions.min.js
[27/Aug/2016 21:21:47] WARNING [django.request:182]                       Not Found: /static/admin/js/prepopulate.min.js
[27/Aug/2016 21:21:55] DEBUG [django.template:927]                       Exception while resolving variable 'errors' in template 'admin/change_list.html'.
Traceback (most recent call last):
  File "/Users/santosh/.virtualenvs/selebmvp/lib/python3.5/site-packages/django/template/base.py", line 883, in _resolve_lookup
    current = current[bit]
TypeError: 'NoneType' object is not subscriptable

During handling of the above exception, another exception occurred:

Traceback (most recent call last):
  File "/Users/santosh/.virtualenvs/selebmvp/lib/python3.5/site-packages/django/template/base.py", line 891, in _resolve_lookup
    current = getattr(current, bit)
AttributeError: 'NoneType' object has no attribute 'errors'

During handling of the above exception, another exception occurred:

Traceback (most recent call last):
  File "/Users/santosh/.virtualenvs/selebmvp/lib/python3.5/site-packages/django/template/base.py", line 898, in _resolve_lookup
    current = current[int(bit)]
ValueError: invalid literal for int() with base 10: 'errors'

During handling of the above exception, another exception occurred:

Traceback (most recent call last):
  File "/Users/santosh/.virtualenvs/selebmvp/lib/python3.5/site-packages/django/template/base.py", line 905, in _resolve_lookup
    (bit, current))  # missing attribute
django.template.base.VariableDoesNotExist: Failed lookup for key [errors] in 'None'
[27/Aug/2016 21:21:55] DEBUG [django.template:927]                       Exception while resolving variable 'show' in template 'admin/change_list.html'.
Traceback (most recent call last):
  File "/Users/santosh/.virtualenvs/selebmvp/lib/python3.5/site-packages/django/template/base.py", line 883, in _resolve_lookup
    current = current[bit]
  File "/Users/santosh/.virtualenvs/selebmvp/lib/python3.5/site-packages/django/template/context.py", line 77, in __getitem__
    raise KeyError(key)
KeyError: 'show'

During handling of the above exception, another exception occurred:

Traceback (most recent call last):
  File "/Users/santosh/.virtualenvs/selebmvp/lib/python3.5/site-packages/django/template/base.py", line 889, in _resolve_lookup
    if isinstance(current, BaseContext) and getattr(type(current), bit):
AttributeError: type object 'RequestContext' has no attribute 'show'

During handling of the above exception, another exception occurred:

Traceback (most recent call last):
  File "/Users/santosh/.virtualenvs/selebmvp/lib/python3.5/site-packages/django/template/base.py", line 898, in _resolve_lookup
    current = current[int(bit)]
ValueError: invalid literal for int() with base 10: 'show'

During handling of the above exception, another exception occurred:

Traceback (most recent call last):
  File "/Users/santosh/.virtualenvs/selebmvp/lib/python3.5/site-packages/django/template/base.py", line 905, in _resolve_lookup
    (bit, current))  # missing attribute
django.template.base.VariableDoesNotExist: Failed lookup for key [show] in "[{'None': None, 'csrf_token': <SimpleLazyObject: <function csrf.<locals>._get_val at 0x108f85158>>, 'False': False, 'True': True}]"
[27/Aug/2016 21:21:55] DEBUG [django.template:927]                       Exception while resolving variable 'is_multipart' in template 'admin/change_list.html'.
Traceback (most recent call last):
  File "/Users/santosh/.virtualenvs/selebmvp/lib/python3.5/site-packages/django/template/base.py", line 883, in _resolve_lookup
    current = current[bit]
TypeError: 'NoneType' object is not subscriptable

During handling of the above exception, another exception occurred:

Traceback (most recent call last):
  File "/Users/santosh/.virtualenvs/selebmvp/lib/python3.5/site-packages/django/template/base.py", line 891, in _resolve_lookup
    current = getattr(current, bit)
AttributeError: 'NoneType' object has no attribute 'is_multipart'

During handling of the above exception, another exception occurred:

Traceback (most recent call last):
  File "/Users/santosh/.virtualenvs/selebmvp/lib/python3.5/site-packages/django/template/base.py", line 898, in _resolve_lookup
    current = current[int(bit)]
ValueError: invalid literal for int() with base 10: 'is_multipart'

During handling of the above exception, another exception occurred:

Traceback (most recent call last):
  File "/Users/santosh/.virtualenvs/selebmvp/lib/python3.5/site-packages/django/template/base.py", line 905, in _resolve_lookup
    (bit, current))  # missing attribute
django.template.base.VariableDoesNotExist: Failed lookup for key [is_multipart] in 'None'
[27/Aug/2016 21:21:55] DEBUG [django.template:927]                       Exception while resolving variable 'non_field_errors' in template 'admin/change_list.html'.
Traceback (most recent call last):
  File "/Users/santosh/.virtualenvs/selebmvp/lib/python3.5/site-packages/django/template/base.py", line 883, in _resolve_lookup
    current = current[bit]
TypeError: 'NoneType' object is not subscriptable

During handling of the above exception, another exception occurred:

Traceback (most recent call last):
  File "/Users/santosh/.virtualenvs/selebmvp/lib/python3.5/site-packages/django/template/base.py", line 891, in _resolve_lookup
    current = getattr(current, bit)
AttributeError: 'NoneType' object has no attribute 'non_field_errors'

During handling of the above exception, another exception occurred:

Traceback (most recent call last):
  File "/Users/santosh/.virtualenvs/selebmvp/lib/python3.5/site-packages/django/template/base.py", line 898, in _resolve_lookup
    current = current[int(bit)]
ValueError: invalid literal for int() with base 10: 'non_field_errors'

During handling of the above exception, another exception occurred:

Traceback (most recent call last):
  File "/Users/santosh/.virtualenvs/selebmvp/lib/python3.5/site-packages/django/template/base.py", line 905, in _resolve_lookup
    (bit, current))  # missing attribute
django.template.base.VariableDoesNotExist: Failed lookup for key [non_field_errors] in 'None'
[27/Aug/2016 21:21:55] DEBUG [django.template:927]                       Exception while resolving variable 'non_field_errors' in template 'admin/change_list.html'.
Traceback (most recent call last):
  File "/Users/santosh/.virtualenvs/selebmvp/lib/python3.5/site-packages/django/template/base.py", line 883, in _resolve_lookup
    current = current[bit]
TypeError: 'NoneType' object is not subscriptable

During handling of the above exception, another exception occurred:

Traceback (most recent call last):
  File "/Users/santosh/.virtualenvs/selebmvp/lib/python3.5/site-packages/django/template/base.py", line 891, in _resolve_lookup
    current = getattr(current, bit)
AttributeError: 'NoneType' object has no attribute 'non_field_errors'

During handling of the above exception, another exception occurred:

Traceback (most recent call last):
  File "/Users/santosh/.virtualenvs/selebmvp/lib/python3.5/site-packages/django/template/base.py", line 898, in _resolve_lookup
    current = current[int(bit)]
ValueError: invalid literal for int() with base 10: 'non_field_errors'

During handling of the above exception, another exception occurred:

Traceback (most recent call last):
  File "/Users/santosh/.virtualenvs/selebmvp/lib/python3.5/site-packages/django/template/base.py", line 905, in _resolve_lookup
    (bit, current))  # missing attribute
django.template.base.VariableDoesNotExist: Failed lookup for key [non_field_errors] in 'None'
[27/Aug/2016 21:21:55] DEBUG [django.template:927]                       Exception while resolving variable 'non_field_errors' in template 'admin/change_list.html'.
Traceback (most recent call last):
  File "/Users/santosh/.virtualenvs/selebmvp/lib/python3.5/site-packages/django/template/base.py", line 883, in _resolve_lookup
    current = current[bit]
TypeError: 'NoneType' object is not subscriptable

During handling of the above exception, another exception occurred:

Traceback (most recent call last):
  File "/Users/santosh/.virtualenvs/selebmvp/lib/python3.5/site-packages/django/template/base.py", line 891, in _resolve_lookup
    current = getattr(current, bit)
AttributeError: 'NoneType' object has no attribute 'non_field_errors'

During handling of the above exception, another exception occurred:

Traceback (most recent call last):
  File "/Users/santosh/.virtualenvs/selebmvp/lib/python3.5/site-packages/django/template/base.py", line 898, in _resolve_lookup
    current = current[int(bit)]
ValueError: invalid literal for int() with base 10: 'non_field_errors'

During handling of the above exception, another exception occurred:

Traceback (most recent call last):
  File "/Users/santosh/.virtualenvs/selebmvp/lib/python3.5/site-packages/django/template/base.py", line 905, in _resolve_lookup
    (bit, current))  # missing attribute
django.template.base.VariableDoesNotExist: Failed lookup for key [non_field_errors] in 'None'
[27/Aug/2016 21:21:55] DEBUG [django.template:927]                       Exception while resolving variable 'non_field_errors' in template 'admin/change_list.html'.
Traceback (most recent call last):
  File "/Users/santosh/.virtualenvs/selebmvp/lib/python3.5/site-packages/django/template/base.py", line 883, in _resolve_lookup
    current = current[bit]
TypeError: 'NoneType' object is not subscriptable

During handling of the above exception, another exception occurred:

Traceback (most recent call last):
  File "/Users/santosh/.virtualenvs/selebmvp/lib/python3.5/site-packages/django/template/base.py", line 891, in _resolve_lookup
    current = getattr(current, bit)
AttributeError: 'NoneType' object has no attribute 'non_field_errors'

During handling of the above exception, another exception occurred:

Traceback (most recent call last):
  File "/Users/santosh/.virtualenvs/selebmvp/lib/python3.5/site-packages/django/template/base.py", line 898, in _resolve_lookup
    current = current[int(bit)]
ValueError: invalid literal for int() with base 10: 'non_field_errors'

During handling of the above exception, another exception occurred:

Traceback (most recent call last):
  File "/Users/santosh/.virtualenvs/selebmvp/lib/python3.5/site-packages/django/template/base.py", line 905, in _resolve_lookup
    (bit, current))  # missing attribute
django.template.base.VariableDoesNotExist: Failed lookup for key [non_field_errors] in 'None'
[27/Aug/2016 21:21:55] WARNING [django.request:182]                       Not Found: /static/admin/js/vendor/jquery/jquery.min.js
[27/Aug/2016 21:21:55] WARNING [django.request:182]                       Not Found: /static/admin/js/actions.min.js
[27/Aug/2016 21:21:55] WARNING [django.request:182]                       Not Found: /static/admin/js/prepopulate.min.js
[27/Aug/2016 21:21:59] DEBUG [django.template:927]                       Exception while resolving variable 'invite' in template 'event_packages.html'.
Traceback (most recent call last):
  File "/Users/santosh/.virtualenvs/selebmvp/lib/python3.5/site-packages/django/template/base.py", line 883, in _resolve_lookup
    current = current[bit]
TypeError: 'Event' object is not subscriptable

During handling of the above exception, another exception occurred:

Traceback (most recent call last):
  File "/Users/santosh/.virtualenvs/selebmvp/lib/python3.5/site-packages/django/template/base.py", line 891, in _resolve_lookup
    current = getattr(current, bit)
  File "/Users/santosh/.virtualenvs/selebmvp/lib/python3.5/site-packages/django/db/models/fields/related_descriptors.py", line 355, in __get__
    self.related.get_accessor_name()
django.db.models.fields.related_descriptors.RelatedObjectDoesNotExist: Event has no invite.
[27/Aug/2016 21:21:59] DEBUG [django.template:927]                       Exception while resolving variable 'invite' in template 'event_packages.html'.
Traceback (most recent call last):
  File "/Users/santosh/.virtualenvs/selebmvp/lib/python3.5/site-packages/django/template/base.py", line 883, in _resolve_lookup
    current = current[bit]
TypeError: 'Event' object is not subscriptable

During handling of the above exception, another exception occurred:

Traceback (most recent call last):
  File "/Users/santosh/.virtualenvs/selebmvp/lib/python3.5/site-packages/django/template/base.py", line 891, in _resolve_lookup
    current = getattr(current, bit)
  File "/Users/santosh/.virtualenvs/selebmvp/lib/python3.5/site-packages/django/db/models/fields/related_descriptors.py", line 355, in __get__
    self.related.get_accessor_name()
django.db.models.fields.related_descriptors.RelatedObjectDoesNotExist: Event has no invite.
[27/Aug/2016 21:21:59] DEBUG [django.template:927]                       Exception while resolving variable 'status' in template 'event_packages.html'.
Traceback (most recent call last):
  File "/Users/santosh/.virtualenvs/selebmvp/lib/python3.5/site-packages/django/template/base.py", line 883, in _resolve_lookup
    current = current[bit]
TypeError: 'RelatedManager' object is not subscriptable

During handling of the above exception, another exception occurred:

Traceback (most recent call last):
  File "/Users/santosh/.virtualenvs/selebmvp/lib/python3.5/site-packages/django/template/base.py", line 891, in _resolve_lookup
    current = getattr(current, bit)
AttributeError: 'RelatedManager' object has no attribute 'status'

During handling of the above exception, another exception occurred:

Traceback (most recent call last):
  File "/Users/santosh/.virtualenvs/selebmvp/lib/python3.5/site-packages/django/template/base.py", line 898, in _resolve_lookup
    current = current[int(bit)]
ValueError: invalid literal for int() with base 10: 'status'

During handling of the above exception, another exception occurred:

Traceback (most recent call last):
  File "/Users/santosh/.virtualenvs/selebmvp/lib/python3.5/site-packages/django/template/base.py", line 905, in _resolve_lookup
    (bit, current))  # missing attribute
django.template.base.VariableDoesNotExist: Failed lookup for key [status] in 'user_packages.Booking.None'
[27/Aug/2016 21:22:19] DEBUG [django.template:927]                       Exception while resolving variable 'invite' in template 'event_packages.html'.
Traceback (most recent call last):
  File "/Users/santosh/.virtualenvs/selebmvp/lib/python3.5/site-packages/django/template/base.py", line 883, in _resolve_lookup
    current = current[bit]
TypeError: 'Event' object is not subscriptable

During handling of the above exception, another exception occurred:

Traceback (most recent call last):
  File "/Users/santosh/.virtualenvs/selebmvp/lib/python3.5/site-packages/django/template/base.py", line 891, in _resolve_lookup
    current = getattr(current, bit)
  File "/Users/santosh/.virtualenvs/selebmvp/lib/python3.5/site-packages/django/db/models/fields/related_descriptors.py", line 355, in __get__
    self.related.get_accessor_name()
django.db.models.fields.related_descriptors.RelatedObjectDoesNotExist: Event has no invite.
[27/Aug/2016 21:22:19] DEBUG [django.template:927]                       Exception while resolving variable 'invite' in template 'event_packages.html'.
Traceback (most recent call last):
  File "/Users/santosh/.virtualenvs/selebmvp/lib/python3.5/site-packages/django/template/base.py", line 883, in _resolve_lookup
    current = current[bit]
TypeError: 'Event' object is not subscriptable

During handling of the above exception, another exception occurred:

Traceback (most recent call last):
  File "/Users/santosh/.virtualenvs/selebmvp/lib/python3.5/site-packages/django/template/base.py", line 891, in _resolve_lookup
    current = getattr(current, bit)
  File "/Users/santosh/.virtualenvs/selebmvp/lib/python3.5/site-packages/django/db/models/fields/related_descriptors.py", line 355, in __get__
    self.related.get_accessor_name()
django.db.models.fields.related_descriptors.RelatedObjectDoesNotExist: Event has no invite.
[27/Aug/2016 21:22:59] DEBUG [django.template:927]                       Exception while resolving variable 'invite' in template 'event_packages.html'.
Traceback (most recent call last):
  File "/Users/santosh/.virtualenvs/selebmvp/lib/python3.5/site-packages/django/template/base.py", line 883, in _resolve_lookup
    current = current[bit]
TypeError: 'Event' object is not subscriptable

During handling of the above exception, another exception occurred:

Traceback (most recent call last):
  File "/Users/santosh/.virtualenvs/selebmvp/lib/python3.5/site-packages/django/template/base.py", line 891, in _resolve_lookup
    current = getattr(current, bit)
  File "/Users/santosh/.virtualenvs/selebmvp/lib/python3.5/site-packages/django/db/models/fields/related_descriptors.py", line 355, in __get__
    self.related.get_accessor_name()
django.db.models.fields.related_descriptors.RelatedObjectDoesNotExist: Event has no invite.
[27/Aug/2016 21:22:59] DEBUG [django.template:927]                       Exception while resolving variable 'invite' in template 'event_packages.html'.
Traceback (most recent call last):
  File "/Users/santosh/.virtualenvs/selebmvp/lib/python3.5/site-packages/django/template/base.py", line 883, in _resolve_lookup
    current = current[bit]
TypeError: 'Event' object is not subscriptable

During handling of the above exception, another exception occurred:

Traceback (most recent call last):
  File "/Users/santosh/.virtualenvs/selebmvp/lib/python3.5/site-packages/django/template/base.py", line 891, in _resolve_lookup
    current = getattr(current, bit)
  File "/Users/santosh/.virtualenvs/selebmvp/lib/python3.5/site-packages/django/db/models/fields/related_descriptors.py", line 355, in __get__
    self.related.get_accessor_name()
django.db.models.fields.related_descriptors.RelatedObjectDoesNotExist: Event has no invite.
[27/Aug/2016 21:24:36] DEBUG [django.template:927]                       Exception while resolving variable 'form' in template 'rsvp_form.html'.
Traceback (most recent call last):
  File "/Users/santosh/.virtualenvs/selebmvp/lib/python3.5/site-packages/django/template/base.py", line 883, in _resolve_lookup
    current = current[bit]
  File "/Users/santosh/.virtualenvs/selebmvp/lib/python3.5/site-packages/django/template/context.py", line 77, in __getitem__
    raise KeyError(key)
KeyError: 'form'

During handling of the above exception, another exception occurred:

Traceback (most recent call last):
  File "/Users/santosh/.virtualenvs/selebmvp/lib/python3.5/site-packages/django/template/base.py", line 889, in _resolve_lookup
    if isinstance(current, BaseContext) and getattr(type(current), bit):
AttributeError: type object 'RequestContext' has no attribute 'form'

During handling of the above exception, another exception occurred:

Traceback (most recent call last):
  File "/Users/santosh/.virtualenvs/selebmvp/lib/python3.5/site-packages/django/template/base.py", line 898, in _resolve_lookup
    current = current[int(bit)]
ValueError: invalid literal for int() with base 10: 'form'

During handling of the above exception, another exception occurred:

Traceback (most recent call last):
  File "/Users/santosh/.virtualenvs/selebmvp/lib/python3.5/site-packages/django/template/base.py", line 905, in _resolve_lookup
    (bit, current))  # missing attribute
django.template.base.VariableDoesNotExist: Failed lookup for key [form] in '[{\'False\': False, \'None\': None, \'True\': True}, {\'user\': <SimpleLazyObject: <function AuthenticationMiddleware.process_request.<locals>.<lambda> at 0x106b7e0d0>>, \'messages\': <django.contrib.messages.storage.fallback.FallbackStorage object at 0x106a35710>, \'perms\': <django.contrib.auth.context_processors.PermWrapper object at 0x106b722b0>, \'DEFAULT_MESSAGE_LEVELS\': {\'DEBUG\': 10, \'WARNING\': 30, \'INFO\': 20, \'SUCCESS\': 25, \'ERROR\': 40}, \'request\': <WSGIRequest: GET \'/events/rsvp/bf764d2e-3d64-4a31-8052-dc47a1e043e2/\'>, \'csrf_token\': <SimpleLazyObject: \'0eWCzJxNN8W8nFku6aYBrdtfbBFDiWiv\'>}, {}, {\'invite\': <Invite: eshaans_birthday_party_01>}, {\'block\': <Block Node: content. Contents: [<TextNode: \'\\n  <main class="auth-body\'>, <django.template.defaulttags.URLNode object at 0x106b490b8>, <TextNode: \'">\\n                  \'>, <django.template.defaulttags.CsrfTokenNode object at 0x106b490f0>, <TextNode: \'\\n\\n                    \'>, <IfNode>, <TextNode: \'\\n                   <div \'>, <Variable Node: invite.uuid>, <TextNode: \'">\\n                  </di\'>]>}]'
